<?xml version="1.0" ?>
<robot name="Astolf_urdf" xmlns:xacro="http://www.ros.org/wiki/xacro">

<xacro:include filename="$(find Astolf_urdf_description)/urdf/materials.xacro" />
<xacro:include filename="$(find Astolf_urdf_description)/urdf/Astolf_urdf.trans" />
<xacro:include filename="$(find Astolf_urdf_description)/urdf/Astolf_urdf.gazebo" />
<link name="base_link">
  <inertial>
    <origin xyz="0.0005019490136826831 -0.0001572799951760828 0.18620132162083142" rpy="0 0 0"/>
    <mass value="15.740460000000004"/>
    <inertia ixx="0.288422" iyy="0.600365" izz="0.8684" ixy="0.0" iyz="0.0" ixz="0.0"/>
  </inertial>
  <visual>
    <origin xyz="0 0 0" rpy="0 0 0"/>
    <geometry>
      <mesh filename="package://Astolf_urdf_description/meshes/base_link.stl" scale="0.001 0.001 0.001"/>
    </geometry>
    <material name="silver"/>
  </visual>
  <collision>
    <origin xyz="0 0 0" rpy="0 0 0"/>
    <geometry>
      <mesh filename="package://Astolf_urdf_description/meshes/base_link.stl" scale="0.001 0.001 0.001"/>
    </geometry>
  </collision>
</link>

<link name="center_profile_1">
  <inertial>
    <origin xyz="0.019999949013682572 -2.799951749104439e-07 0.6500000216791524" rpy="0 0 0"/>
    <mass value="5.616"/>
    <inertia ixx="0.791669" iyy="0.791669" izz="0.001498" ixy="0.0" iyz="-0.0" ixz="0.0"/>
  </inertial>
  <visual>
    <origin xyz="-0.275502 0.000157 -0.145508" rpy="0 0 0"/>
    <geometry>
      <mesh filename="package://Astolf_urdf_description/meshes/center_profile_1.stl" scale="0.001 0.001 0.001"/>
    </geometry>
    <material name="silver"/>
  </visual>
  <collision>
    <origin xyz="-0.275502 0.000157 -0.145508" rpy="0 0 0"/>
    <geometry>
      <mesh filename="package://Astolf_urdf_description/meshes/center_profile_1.stl" scale="0.001 0.001 0.001"/>
    </geometry>
  </collision>
</link>

<link name="lidar_suport_1">
  <inertial>
    <origin xyz="0.5499999490136825 0.24999972000482418 0.11300002167915246" rpy="0 0 0"/>
    <mass value="0.10692000000000024"/>
    <inertia ixx="0.000128" iyy="0.000108" izz="0.000236" ixy="0.0" iyz="-0.0" ixz="0.0"/>
  </inertial>
  <visual>
    <origin xyz="0.179498 0.250157 -0.165508" rpy="0 0 0"/>
    <geometry>
      <mesh filename="package://Astolf_urdf_description/meshes/lidar_suport_1.stl" scale="0.001 0.001 0.001"/>
    </geometry>
    <material name="silver"/>
  </visual>
  <collision>
    <origin xyz="0.179498 0.250157 -0.165508" rpy="0 0 0"/>
    <geometry>
      <mesh filename="package://Astolf_urdf_description/meshes/lidar_suport_1.stl" scale="0.001 0.001 0.001"/>
    </geometry>
  </collision>
</link>

<link name="realsense_suport_1">
  <inertial>
    <origin xyz="0.4947231360152813 0.2499685125835737 0.03257630512957688" rpy="0 0 0"/>
    <mass value="0.10595838064168012"/>
    <inertia ixx="0.000143" iyy="0.000143" izz="1.4e-05" ixy="-0.0" iyz="0.0" ixz="-0.0"/>
  </inertial>
  <visual>
    <origin xyz="0.199498 0.250157 -1.465508" rpy="0 0 0"/>
    <geometry>
      <mesh filename="package://Astolf_urdf_description/meshes/realsense_suport_1.stl" scale="0.001 0.001 0.001"/>
    </geometry>
    <material name="silver"/>
  </visual>
  <collision>
    <origin xyz="0.199498 0.250157 -1.465508" rpy="0 0 0"/>
    <geometry>
      <mesh filename="package://Astolf_urdf_description/meshes/realsense_suport_1.stl" scale="0.001 0.001 0.001"/>
    </geometry>
  </collision>
</link>

<link name="front_m_1">
  <inertial>
    <origin xyz="0.19499994901368256 0.24999972000482393 -0.03999997832084756" rpy="0 0 0"/>
    <mass value="4.772799999999999"/>
    <inertia ixx="0.058069" iyy="0.001273" izz="0.058069" ixy="0.0" iyz="0.0" ixz="-0.0"/>
  </inertial>
  <visual>
    <origin xyz="-0.000502 0.250157 -0.165508" rpy="0 0 0"/>
    <geometry>
      <mesh filename="package://Astolf_urdf_description/meshes/front_m_1.stl" scale="0.001 0.001 0.001"/>
    </geometry>
    <material name="silver"/>
  </visual>
  <collision>
    <origin xyz="-0.000502 0.250157 -0.165508" rpy="0 0 0"/>
    <geometry>
      <mesh filename="package://Astolf_urdf_description/meshes/front_m_1.stl" scale="0.001 0.001 0.001"/>
    </geometry>
  </collision>
</link>

<link name="back_m_1">
  <inertial>
    <origin xyz="-0.20500005098631743 0.24999972000482393 -0.03999997832084756" rpy="0 0 0"/>
    <mass value="4.772799999999999"/>
    <inertia ixx="0.058069" iyy="0.001273" izz="0.058069" ixy="0.0" iyz="-0.0" ixz="-0.0"/>
  </inertial>
  <visual>
    <origin xyz="-0.000502 0.250157 -0.165508" rpy="0 0 0"/>
    <geometry>
      <mesh filename="package://Astolf_urdf_description/meshes/back_m_1.stl" scale="0.001 0.001 0.001"/>
    </geometry>
    <material name="silver"/>
  </visual>
  <collision>
    <origin xyz="-0.000502 0.250157 -0.165508" rpy="0 0 0"/>
    <geometry>
      <mesh filename="package://Astolf_urdf_description/meshes/back_m_1.stl" scale="0.001 0.001 0.001"/>
    </geometry>
  </collision>
</link>

<link name="front_right_wheel_1">
  <inertial>
    <origin xyz="-5.098631744582249e-08 -0.04000027999517608 2.1679152389930678e-08" rpy="0 0 0"/>
    <mass value="3.531183471946012"/>
    <inertia ixx="0.015179" iyy="0.02677" izz="0.015179" ixy="0.0" iyz="-0.0" ixz="-0.0"/>
  </inertial>
  <visual>
    <origin xyz="-0.195502 0.190157 -0.125508" rpy="0 0 0"/>
    <geometry>
      <mesh filename="package://Astolf_urdf_description/meshes/front_right_wheel_1.stl" scale="0.001 0.001 0.001"/>
    </geometry>
    <material name="silver"/>
  </visual>
  <collision>
    <origin xyz="-0.195502 0.190157 -0.125508" rpy="0 0 0"/>
    <geometry>
      <mesh filename="package://Astolf_urdf_description/meshes/front_right_wheel_1.stl" scale="0.001 0.001 0.001"/>
    </geometry>
  </collision>
</link>

<link name="front_left_wheel_1">
  <inertial>
    <origin xyz="-5.0986317362555766e-08 0.039999720004823824 2.1679152417686254e-08" rpy="0 0 0"/>
    <mass value="3.5311834719460093"/>
    <inertia ixx="0.015179" iyy="0.02677" izz="0.015179" ixy="-0.0" iyz="-0.0" ixz="-0.0"/>
  </inertial>
  <visual>
    <origin xyz="-0.195502 -0.189843 -0.125508" rpy="0 0 0"/>
    <geometry>
      <mesh filename="package://Astolf_urdf_description/meshes/front_left_wheel_1.stl" scale="0.001 0.001 0.001"/>
    </geometry>
    <material name="silver"/>
  </visual>
  <collision>
    <origin xyz="-0.195502 -0.189843 -0.125508" rpy="0 0 0"/>
    <geometry>
      <mesh filename="package://Astolf_urdf_description/meshes/front_left_wheel_1.stl" scale="0.001 0.001 0.001"/>
    </geometry>
  </collision>
</link>

<link name="back_right_wheel_1">
  <inertial>
    <origin xyz="-5.098631741806692e-08 -0.04000027999517605 2.1679152417686254e-08" rpy="0 0 0"/>
    <mass value="3.5311834719460125"/>
    <inertia ixx="0.015179" iyy="0.02677" izz="0.015179" ixy="-0.0" iyz="0.0" ixz="0.0"/>
  </inertial>
  <visual>
    <origin xyz="0.204498 0.190157 -0.125508" rpy="0 0 0"/>
    <geometry>
      <mesh filename="package://Astolf_urdf_description/meshes/back_right_wheel_1.stl" scale="0.001 0.001 0.001"/>
    </geometry>
    <material name="silver"/>
  </visual>
  <collision>
    <origin xyz="0.204498 0.190157 -0.125508" rpy="0 0 0"/>
    <geometry>
      <mesh filename="package://Astolf_urdf_description/meshes/back_right_wheel_1.stl" scale="0.001 0.001 0.001"/>
    </geometry>
  </collision>
</link>

<link name="back_left_wheel_1">
  <inertial>
    <origin xyz="-5.098631741806692e-08 0.03999972000482391 2.1679152417686254e-08" rpy="0 0 0"/>
    <mass value="3.5311834719460125"/>
    <inertia ixx="0.015179" iyy="0.02677" izz="0.015179" ixy="-0.0" iyz="-0.0" ixz="0.0"/>
  </inertial>
  <visual>
    <origin xyz="0.204498 -0.189843 -0.125508" rpy="0 0 0"/>
    <geometry>
      <mesh filename="package://Astolf_urdf_description/meshes/back_left_wheel_1.stl" scale="0.001 0.001 0.001"/>
    </geometry>
    <material name="silver"/>
  </visual>
  <collision>
    <origin xyz="0.204498 -0.189843 -0.125508" rpy="0 0 0"/>
    <geometry>
      <mesh filename="package://Astolf_urdf_description/meshes/back_left_wheel_1.stl" scale="0.001 0.001 0.001"/>
    </geometry>
  </collision>
</link>

<link name="realsense_v1_1">
  <inertial>
    <origin xyz="0.0019013299758136593 0.0002471103422558397 0.012439157194748862" rpy="0 0 0"/>
    <mass value="0.3513213158108225"/>
    <inertia ixx="0.000227" iyy="3.2e-05" izz="0.000229" ixy="-1e-06" iyz="-0.0" ixz="-0.0"/>
  </inertial>
  <visual>
    <origin xyz="-0.295173 0.000179 -1.575508" rpy="0 0 0"/>
    <geometry>
      <mesh filename="package://Astolf_urdf_description/meshes/realsense_v1_1.stl" scale="0.001 0.001 0.001"/>
    </geometry>
    <material name="silver"/>
  </visual>
  <collision>
    <origin xyz="-0.295173 0.000179 -1.575508" rpy="0 0 0"/>
    <geometry>
      <mesh filename="package://Astolf_urdf_description/meshes/realsense_v1_1.stl" scale="0.001 0.001 0.001"/>
    </geometry>
  </collision>
</link>

<link name="imu_v2_1">
  <inertial>
    <origin xyz="-8.255948388489467e-07 -2.2100343875138266e-06 0.001172304932095719" rpy="0 0 0"/>
    <mass value="0.010319775464356156"/>
    <inertia ixx="0.0" iyy="1e-06" izz="1e-06" ixy="0.0" iyz="0.0" ixz="0.0"/>
  </inertial>
  <visual>
    <origin xyz="-0.000502 0.000157 -0.147508" rpy="0 0 0"/>
    <geometry>
      <mesh filename="package://Astolf_urdf_description/meshes/imu_v2_1.stl" scale="0.001 0.001 0.001"/>
    </geometry>
    <material name="silver"/>
  </visual>
  <collision>
    <origin xyz="-0.000502 0.000157 -0.147508" rpy="0 0 0"/>
    <geometry>
      <mesh filename="package://Astolf_urdf_description/meshes/imu_v2_1.stl" scale="0.001 0.001 0.001"/>
    </geometry>
  </collision>
</link>

<link name="rplidar_a1_v4_1">
  <inertial>
    <origin xyz="0.22718906129107017 0.31100088458894426 0.0073159259596849435" rpy="0 0 0"/>
    <mass value="0.16092740340489478"/>
    <inertia ixx="6e-05" iyy="0.000123" izz="0.000149" ixy="0.0" iyz="0.0" ixz="-1.8e-05"/>
  </inertial>
  <visual>
    <origin xyz="-0.150502 0.310157 -0.303007" rpy="0 0 0"/>
    <geometry>
      <mesh filename="package://Astolf_urdf_description/meshes/rplidar_a1_v4_1.stl" scale="0.001 0.001 0.001"/>
    </geometry>
    <material name="silver"/>
  </visual>
  <collision>
    <origin xyz="-0.150502 0.310157 -0.303007" rpy="0 0 0"/>
    <geometry>
      <mesh filename="package://Astolf_urdf_description/meshes/rplidar_a1_v4_1.stl" scale="0.001 0.001 0.001"/>
    </geometry>
  </collision>
</link>

<joint name="Rigid1" type="fixed">
  <origin xyz="0.275502 -0.000157 0.145508" rpy="0 0 0"/>
  <parent link="base_link"/>
  <child link="center_profile_1"/>
</joint>

<joint name="Rigid2" type="fixed">
  <origin xyz="-0.455 -0.25 0.02" rpy="0 0 0"/>
  <parent link="center_profile_1"/>
  <child link="lidar_suport_1"/>
</joint>

<joint name="Rigid3" type="fixed">
  <origin xyz="-0.475 -0.25 1.32" rpy="0 0 0"/>
  <parent link="center_profile_1"/>
  <child link="realsense_suport_1"/>
</joint>

<joint name="Rigid9" type="fixed">
  <origin xyz="0.000502 -0.250157 0.165508" rpy="0 0 0"/>
  <parent link="base_link"/>
  <child link="front_m_1"/>
</joint>

<joint name="Rigid10" type="fixed">
  <origin xyz="0.000502 -0.250157 0.165508" rpy="0 0 0"/>
  <parent link="base_link"/>
  <child link="back_m_1"/>
</joint>

<joint name="Rev11" type="continuous">
  <origin xyz="0.195 0.06 -0.04" rpy="0 0 0"/>
  <parent link="front_m_1"/>
  <child link="front_right_wheel_1"/>
  <axis xyz="0.0 -1.0 0.0"/>
</joint>

<joint name="Rev12" type="continuous">
  <origin xyz="0.195 0.44 -0.04" rpy="0 0 0"/>
  <parent link="front_m_1"/>
  <child link="front_left_wheel_1"/>
  <axis xyz="-0.0 1.0 0.0"/>
</joint>

<joint name="Rev13" type="continuous">
  <origin xyz="-0.205 0.06 -0.04" rpy="0 0 0"/>
  <parent link="back_m_1"/>
  <child link="back_right_wheel_1"/>
  <axis xyz="0.0 -1.0 0.0"/>
</joint>

<joint name="Rev14" type="continuous">
  <origin xyz="-0.205 0.44 -0.04" rpy="0 0 0"/>
  <parent link="back_m_1"/>
  <child link="back_left_wheel_1"/>
  <axis xyz="-0.0 1.0 0.0"/>
</joint>

<joint name="Rigid15" type="fixed">
  <origin xyz="0.494671 0.249978 0.11" rpy="0 0 0"/>
  <parent link="realsense_suport_1"/>
  <child link="realsense_v1_1"/>
</joint>

<joint name="Rigid16" type="fixed">
  <origin xyz="0.000502 -0.000157 0.147508" rpy="0 0 0"/>
  <parent link="base_link"/>
  <child link="imu_v2_1"/>
</joint>

<joint name="Rigid17" type="fixed">
  <origin xyz="0.33 -0.06 0.137499" rpy="0 0 0"/>
  <parent link="lidar_suport_1"/>
  <child link="rplidar_a1_v4_1"/>
</joint>

</robot>
